2025-08-05 21:38:25,449 - INFO - Браузер успішно запущено
2025-08-05 21:38:25,450 - INFO - Заповнення першої сторінки реєстрації
2025-08-05 21:38:54,903 - INFO - Перша сторінка успішно заповнена
2025-08-05 21:38:54,903 - INFO - Заповнення другої сторінки реєстрації
2025-08-05 21:39:13,475 - INFO - Друга сторінка успішно заповнена
2025-08-05 21:39:15,476 - INFO - Заповнення третьої сторінки реєстрації
2025-08-05 21:39:23,092 - INFO - Форма успішно відправлена, очікування відповіді...
2025-08-05 21:39:36,919 - INFO - Браузер успішно закрито
2025-08-05 21:39:43,482 - INFO - Браузер успішно запущено
2025-08-05 21:39:43,482 - INFO - Заповнення першої сторінки реєстрації
2025-08-05 21:40:11,074 - INFO - Перша сторінка успішно заповнена
2025-08-05 21:40:11,103 - INFO - Заповнення другої сторінки реєстрації
2025-08-05 21:40:28,748 - INFO - Друга сторінка успішно заповнена
2025-08-05 21:40:30,749 - INFO - Заповнення третьої сторінки реєстрації
2025-08-05 21:40:37,905 - INFO - Форма успішно відправлена, очікування відповіді...
2025-08-05 21:40:51,451 - INFO - Браузер успішно закрито
2025-08-05 21:40:57,516 - INFO - Браузер успішно запущено
2025-08-05 21:40:57,516 - INFO - Заповнення першої сторінки реєстрації
2025-08-05 21:41:26,109 - INFO - Перша сторінка успішно заповнена
2025-08-05 21:41:26,109 - INFO - Заповнення другої сторінки реєстрації
2025-08-05 21:41:43,919 - INFO - Друга сторінка успішно заповнена
2025-08-05 21:41:45,920 - INFO - Заповнення третьої сторінки реєстрації
2025-08-05 21:41:53,423 - INFO - Форма успішно відправлена, очікування відповіді...
2025-08-05 21:42:22,833 - INFO - Браузер успішно закрито
2025-08-05 21:42:29,160 - INFO - Браузер успішно запущено
2025-08-05 21:42:29,161 - INFO - Заповнення першої сторінки реєстрації
2025-08-05 21:42:59,433 - INFO - Перша сторінка успішно заповнена
2025-08-05 21:42:59,433 - INFO - Заповнення другої сторінки реєстрації
2025-08-05 21:43:16,570 - INFO - Друга сторінка успішно заповнена
2025-08-05 21:43:18,571 - INFO - Заповнення третьої сторінки реєстрації
2025-08-05 21:43:24,941 - INFO - Форма успішно відправлена, очікування відповіді...
2025-08-05 21:43:49,654 - INFO - Браузер успішно закрито
2025-08-05 21:43:50,075 - INFO - Отримано сигнал зупинки. Завершення роботи.
2025-08-05 22:00:13,753 - INFO - Processing record 1/6
2025-08-05 22:15:08,980 - INFO - Processing record 1/6
2025-08-05 22:15:41,764 - INFO - Registration result: BAD - Unknown status
2025-08-05 22:15:44,360 - INFO - Processing record 2/6
2025-08-05 22:16:12,610 - INFO - Registration result: BAD - Unknown status
2025-08-05 22:16:15,074 - INFO - Processing record 3/6
2025-08-05 22:16:43,065 - INFO - Registration result: BAD - Unknown status
2025-08-05 22:16:45,531 - INFO - Processing record 4/6
2025-08-05 22:23:42,000 - INFO - Processing record 1/3
2025-08-05 22:24:11,230 - ERROR - Error during registration: 
Traceback (most recent call last):
  File "D:\PycharmProjects\automations\automation\parimatch.py", line 120, in run_automation_parimatch
    write(address, into='Address Line 1')
    ~~~~~^^^^^^^^^^^^^^^^^^^^^^^^^^^^^^^^
  File "D:\PycharmProjects\automations\.venv\Lib\site-packages\helium\__init__.py", line 173, in write
    _get_api_impl().write_impl(text, into)
    ~~~~~~~~~~~~~~~~~~~~~~~~~~^^^^^^^^^^^^
  File "D:\PycharmProjects\automations\.venv\Lib\site-packages\helium\_impl\__init__.py", line 36, in f_decorated
    result = f(self, *args, **kwargs)
  File "D:\PycharmProjects\automations\.venv\Lib\site-packages\helium\_impl\__init__.py", line 55, in f_decorated
    return f(*args, **kwargs)
  File "D:\PycharmProjects\automations\.venv\Lib\site-packages\helium\_impl\__init__.py", line 143, in write_impl
    self._handle_alerts(
    ~~~~~~~~~~~~~~~~~~~^
    	self._write_no_alert, self._write_with_alert, text, into=into
     ^^^^^^^^^^^^^^^^^^^^^^^^^^^^^^^^^^^^^^^^^^^^^^^^^^^^^^^^^^^^^
    )
    ^
  File "D:\PycharmProjects\automations\.venv\Lib\site-packages\helium\_impl\__init__.py", line 168, in _handle_alerts
    return no_alert(*args, **kwargs)
  File "D:\PycharmProjects\automations\.venv\Lib\site-packages\helium\_impl\__init__.py", line 154, in _write_no_alert
    self._manipulate(into, _write)
    ~~~~~~~~~~~~~~~~^^^^^^^^^^^^^^
  File "D:\PycharmProjects\automations\.venv\Lib\site-packages\helium\_impl\__init__.py", line 283, in _manipulate
    driver.last_manipulated_element = gui_or_web_elt.perform(action)
                                      ~~~~~~~~~~~~~~~~~~~~~~^^^^^^^^
  File "D:\PycharmProjects\automations\.venv\Lib\site-packages\helium\_impl\__init__.py", line 639, in perform
    raise LookupError()
LookupError
2025-08-05 22:24:13,855 - INFO - Processing record 2/3
2025-08-05 22:24:27,859 - INFO - Processing record 1/3
2025-08-05 22:24:56,121 - INFO - Registration result: BAD - Unknown status
2025-08-05 22:24:58,624 - INFO - Processing record 2/3
2025-08-05 22:25:00,402 - ERROR - Error during registration: ('Connection aborted.', ConnectionResetError(10054, 'An existing connection was forcibly closed by the remote host', None, 10054, None))
Traceback (most recent call last):
  File "D:\PycharmProjects\automations\.venv\Lib\site-packages\urllib3\connectionpool.py", line 787, in urlopen
    response = self._make_request(
        conn,
    ...<10 lines>...
        **response_kw,
    )
  File "D:\PycharmProjects\automations\.venv\Lib\site-packages\urllib3\connectionpool.py", line 534, in _make_request
    response = conn.getresponse()
  File "D:\PycharmProjects\automations\.venv\Lib\site-packages\urllib3\connection.py", line 516, in getresponse
    httplib_response = super().getresponse()
  File "C:\Users\Dmytro\AppData\Local\Programs\Python\Python313\Lib\http\client.py", line 1430, in getresponse
    response.begin()
    ~~~~~~~~~~~~~~^^
  File "C:\Users\Dmytro\AppData\Local\Programs\Python\Python313\Lib\http\client.py", line 331, in begin
    version, status, reason = self._read_status()
                              ~~~~~~~~~~~~~~~~~^^
  File "C:\Users\Dmytro\AppData\Local\Programs\Python\Python313\Lib\http\client.py", line 292, in _read_status
    line = str(self.fp.readline(_MAXLINE + 1), "iso-8859-1")
               ~~~~~~~~~~~~~~~~^^^^^^^^^^^^^^
  File "C:\Users\Dmytro\AppData\Local\Programs\Python\Python313\Lib\socket.py", line 719, in readinto
    return self._sock.recv_into(b)
           ~~~~~~~~~~~~~~~~~~~~^^^
ConnectionResetError: [WinError 10054] An existing connection was forcibly closed by the remote host

During handling of the above exception, another exception occurred:

Traceback (most recent call last):
  File "D:\PycharmProjects\automations\automation\parimatch.py", line 90, in run_automation_parimatch
    driver = start_chrome(PAGE_URL)
  File "D:\PycharmProjects\automations\.venv\Lib\site-packages\helium\__init__.py", line 65, in start_chrome
    return _get_api_impl().start_chrome_impl(url, headless, maximize, options)
           ~~~~~~~~~~~~~~~~~~~~~~~~~~~~~~~~~^^^^^^^^^^^^^^^^^^^^^^^^^^^^^^^^^^
  File "D:\PycharmProjects\automations\.venv\Lib\site-packages\helium\_impl\__init__.py", line 98, in start_chrome_impl
    return self._start(chrome_driver, url)
           ~~~~~~~~~~~^^^^^^^^^^^^^^^^^^^^
  File "D:\PycharmProjects\automations\.venv\Lib\site-packages\helium\_impl\__init__.py", line 123, in _start
    self.go_to_impl(url)
    ~~~~~~~~~~~~~~~^^^^^
  File "D:\PycharmProjects\automations\.venv\Lib\site-packages\helium\_impl\__init__.py", line 36, in f_decorated
    result = f(self, *args, **kwargs)
  File "D:\PycharmProjects\automations\.venv\Lib\site-packages\helium\_impl\__init__.py", line 55, in f_decorated
    return f(*args, **kwargs)
  File "D:\PycharmProjects\automations\.venv\Lib\site-packages\helium\_impl\__init__.py", line 130, in go_to_impl
    self.require_driver().get(url)
    ~~~~~~~~~~~~~~~~~~~~~~~~~^^^^^
  File "D:\PycharmProjects\automations\.venv\Lib\site-packages\selenium\webdriver\remote\webdriver.py", line 454, in get
    self.execute(Command.GET, {"url": url})
    ~~~~~~~~~~~~^^^^^^^^^^^^^^^^^^^^^^^^^^^
  File "D:\PycharmProjects\automations\.venv\Lib\site-packages\selenium\webdriver\remote\webdriver.py", line 427, in execute
    response = self.command_executor.execute(driver_command, params)
  File "D:\PycharmProjects\automations\.venv\Lib\site-packages\selenium\webdriver\remote\remote_connection.py", line 404, in execute
    return self._request(command_info[0], url, body=data)
           ~~~~~~~~~~~~~^^^^^^^^^^^^^^^^^^^^^^^^^^^^^^^^^
  File "D:\PycharmProjects\automations\.venv\Lib\site-packages\selenium\webdriver\remote\remote_connection.py", line 428, in _request
    response = self._conn.request(method, url, body=body, headers=headers, timeout=self._client_config.timeout)
  File "D:\PycharmProjects\automations\.venv\Lib\site-packages\urllib3\_request_methods.py", line 143, in request
    return self.request_encode_body(
           ~~~~~~~~~~~~~~~~~~~~~~~~^
        method, url, fields=fields, headers=headers, **urlopen_kw
        ^^^^^^^^^^^^^^^^^^^^^^^^^^^^^^^^^^^^^^^^^^^^^^^^^^^^^^^^^
    )
    ^
  File "D:\PycharmProjects\automations\.venv\Lib\site-packages\urllib3\_request_methods.py", line 278, in request_encode_body
    return self.urlopen(method, url, **extra_kw)
           ~~~~~~~~~~~~^^^^^^^^^^^^^^^^^^^^^^^^^
  File "D:\PycharmProjects\automations\.venv\Lib\site-packages\urllib3\poolmanager.py", line 443, in urlopen
    response = conn.urlopen(method, u.request_uri, **kw)
  File "D:\PycharmProjects\automations\.venv\Lib\site-packages\urllib3\connectionpool.py", line 841, in urlopen
    retries = retries.increment(
        method, url, error=new_e, _pool=self, _stacktrace=sys.exc_info()[2]
    )
  File "D:\PycharmProjects\automations\.venv\Lib\site-packages\urllib3\util\retry.py", line 474, in increment
    raise reraise(type(error), error, _stacktrace)
          ~~~~~~~^^^^^^^^^^^^^^^^^^^^^^^^^^^^^^^^^
  File "D:\PycharmProjects\automations\.venv\Lib\site-packages\urllib3\util\util.py", line 38, in reraise
    raise value.with_traceback(tb)
  File "D:\PycharmProjects\automations\.venv\Lib\site-packages\urllib3\connectionpool.py", line 787, in urlopen
    response = self._make_request(
        conn,
    ...<10 lines>...
        **response_kw,
    )
  File "D:\PycharmProjects\automations\.venv\Lib\site-packages\urllib3\connectionpool.py", line 534, in _make_request
    response = conn.getresponse()
  File "D:\PycharmProjects\automations\.venv\Lib\site-packages\urllib3\connection.py", line 516, in getresponse
    httplib_response = super().getresponse()
  File "C:\Users\Dmytro\AppData\Local\Programs\Python\Python313\Lib\http\client.py", line 1430, in getresponse
    response.begin()
    ~~~~~~~~~~~~~~^^
  File "C:\Users\Dmytro\AppData\Local\Programs\Python\Python313\Lib\http\client.py", line 331, in begin
    version, status, reason = self._read_status()
                              ~~~~~~~~~~~~~~~~~^^
  File "C:\Users\Dmytro\AppData\Local\Programs\Python\Python313\Lib\http\client.py", line 292, in _read_status
    line = str(self.fp.readline(_MAXLINE + 1), "iso-8859-1")
               ~~~~~~~~~~~~~~~~^^^^^^^^^^^^^^
  File "C:\Users\Dmytro\AppData\Local\Programs\Python\Python313\Lib\socket.py", line 719, in readinto
    return self._sock.recv_into(b)
           ~~~~~~~~~~~~~~~~~~~~^^^
urllib3.exceptions.ProtocolError: ('Connection aborted.', ConnectionResetError(10054, 'An existing connection was forcibly closed by the remote host', None, 10054, None))
